Workbook
Name AccessKey_User_Help_Desk: #REF!
Name AccessKey_User_Help_Desk: #REF!
Name Call_Transfer_Method_List: #REF!
Name Connectivity_Date: #REF!
Name Department_Abbr_List: #REF!
Name Department_Name: 'Client Tier 1'!$C$3
Name Department_Name: #REF!
Name Department_Name_Concatenated_List: #REF!
Name Department_Name_List: #REF!
Name Department_Table: #REF!
Name Department_Table_Headings: #REF!
Name Dept_Abbr: 'Client Tier 1'!$C$2
Name Dept_Abbr: #REF!
Name dff: #REF!
Name DFO: [1]Lookups!$B$12:$D$34
Name Environment_Selected: #REF!
Name GCBCS_User_Help_Desk: #REF!
Name GCBCS_User_Help_Desk: #REF!
Name Production_Authorized: 'Client Tier 2'!$C$40:$H$46
Name Production_Incident_Notification: 'Client Tier 2'!$C$61:$H$65
Name Production_Technical: 'Client Tier 2'!$C$51:$H$56
Name Program_Description: 'Client Tier 1'!$C$5
Name Program_Description: #REF!
Name Program_Name: 'Client Tier 1'!$C$4
Name Program_Name: #REF!
Name SecureKey_User_Help_Desk: #REF!
Name SecureKey_User_Help_Desk: #REF!
Name Selected_SSC_SM: #REF!
Name Service_Contacts_Table: #REF!
Name Service_Selected: #REF!
Name Service_User_Help_Desk_Contacts: #REF!
Name Service_User_Help_Desk_Contacts: #REF!
Name SPOC_Level_2: 'Client Tier 2'!$C$71:$H$72
Name Test_Authorized: 'Client Tier 2'!$C$12:$H$18
Name Test_Incident_Notification: 'Client Tier 2'!$C$23:$H$29
Name User_Community: 'Client Tier 1'!$C$6
Name User_Community: #REF!
Name User_Community_Users: 'Client Tier 1'!$C$7
Name User_Community_Users: #REF!
Name VMS: [1]Lookups!$B$11:$D$11

Sheet Client Tier 1
B1: Program / Line of Business
A2: 1 | B2: Department (abbr.)
A3: 2 | B3: Department Name
A4: 3 | B4: Program / Line of Business Name
A5: 4 | B5: Program / Line of Business Description
A6: 5 | B6: User community served by the Program / Line of Business
A7: 6 | B7: User community number of users
B9: Application Owner Tier 1 Help Desk Contacts
A10: 7 | B10: General Enquiry Calls | C10: The NS Login Support Help Desk will transfer general enquiries from users, related to your organization, but unrelated to your application to these numbers.
D11: Phone Number | E11: Hours of Operation
C12: English
C13: French
C14: TTY/TDD
C15: Collect calls
A17: 8 | B17: Application-Related Calls | C17: The NS Login Support Help Desk will transfer calls related to your application to these numbers.
D18: Phone Number | E18: Hours of Operation
B19: Program | C19: English
C20: French
B22: Technical | C22: English
C23: French
B25: Other | C25: English
C26: French
C27: Email
B29: International | C29: International
B31: TTY/TDD | C31: English
C32: French
B34: Other | C34: English
C35: French
B37: Collect calls | C37: Collect
A39: 9 | B39: How will the Login Support Help Desk transfer calls to Tier 1 Contact Centre?
A40: 10 | B40: How will Tier 1 Contact Centre transfer calls to the Login Support Help Desk?
B42: Notes

Sheet Client Tier 2
B1: Program / Line of Business Information
A2: 1 | B2: Department Name | D2: ='Client Tier 1'!C3:E3 -> 0
A3: 2 | B3: Program / Line of Business Name | D3: ='Client Tier 1'!C4:E4 -> 0
A4: 3 | B4: Program / Line of Business Description | D4: ='Client Tier 1'!C5:E5 -> 0
A5: 4 | B5: User Community served by the Program / Line of Business | D5: ='Client Tier 1'!C6:E6 -> 0
A6: 5 | B6: User community number of users | D6: ='Client Tier 1'!C7:E7 -> 0
A8: ` | B8: Test Environment Contacts
A9: 6 | B9: Authorized Individuals -Test Environment (Shared Secret)
B10: The following people are authorized to communicate with the Login Support Tier 2 Help Desk about the Test environment. Examples: Application Tier 2 team, Help Desk Manager.
B11: =B$39 -> Item | C11: =C$39 -> Full Name | D11: =D$39 -> Role | E11: =E$39 -> Phone No | F11: =F$39 -> Cell No | G11: =G$39 -> Pager | H11: =H$39 -> Email Address
B12: 0.1
B13: 0.2
B14: 0.3
B15: 0.4
B16: 0.5
B17: 0.6
B18: 0.7
A20: 7 | B20: Incident Notifications - Test Environment
B21: The Login Support Tier 2 Help Desk will e-mail Severity 1 (Service Outage) and Severity 2 (Service Degradation) incident notifications for the Test Environment to the following e-mail addresses (include at least the Tier 1 Help Desk and use more than address to ensure availability and coverage).
B22: =B$39 -> Item | C22: =C$39 -> Full Name | D22: =D$39 -> Role | E22: =E$39 -> Phone No | F22: =F$39 -> Cell No | G22: =G$39 -> Pager | H22: =H$39 -> Email Address
B23: 0.1
B24: 0.2
B25: 0.3
B26: 0.4
B27: 0.5
B28: 0.6
B29: 0.7
B31: Production Environment Contacts - Tier 2 Help Desk
B32: The Login Tier 2 Help Desk will establish a Shared Secret with each unique person listed below
A33: 8 | B33: Tier 2 Help Desk Name
A34: 9 | B34: Tier 2 Help Desk central phone number
A35: 10 | B35: Tier 2 Help Desk hours of operation
A37: 11 | B37: Authorized Individuals - Production Environment (Shared Secret)
B38: The following people are authorized to communicate with the Login Support Tier 2 Help Desk about the Production environment. Examples: Tier 2 Help Desk team and Help Desk Manager (escalation point).
B39: Item | C39: Full Name | D39: Role | E39: Phone No | F39: Cell No | G39: Pager | H39: Email Address
B40: 0.1
B41: 0.2
B42: 0.3
B43: 0.4
B44: 0.5
...
